<?xml version='1.0'?>
<sdf version='1.6'>
  <model name='R.A.L._X6'>
    <link name='base_link'>
      <pose frame=''>0 0 0.173237 0 -0 0</pose>
      <inertial>
        <pose frame=''>0.001005 0 -0.009004 0 -0 0</pose>
        <mass>2.02</mass>
        <inertia>
          <ixx>0.011</ixx>
          <ixy>0</ixy>
          <ixz>0</ixz>
          <iyy>0.015</iyy>
          <iyz>0</iyz>
          <izz>0.021</izz>
        </inertia>
      </inertial>
      <gravity>1</gravity>
      <velocity_decay/>
      <self_collide>0</self_collide>
      <enable_wind>0</enable_wind>
      <kinematic>0</kinematic>
      <visual name='base_link_visual'>
        <pose frame=''>0 0 0 0 -0 0</pose>
        <geometry>
          <mesh>
            <scale>0.001 0.001 0.001</scale>
            <uri>model://ral_x6/meshes/ral_x6_v2.stl</uri>
          </mesh>
        </geometry>
        <material>
          <script>
            <name>Gazebo/DarkGrey</name>
            <uri>file://media/materials/scripts/gazebo.material</uri>
          </script>
          <shader type='pixel'>
            <normal_map>__default__</normal_map>
          </shader>
          <ambient>0.175 0.175 0.175 1</ambient>
          <diffuse>0.175 0.175 0.175 1</diffuse>
          <specular>0.175 0.175 0.175 1</specular>
          <emissive>0 0 0 1</emissive>
        </material>
        <transparency>0</transparency>
        <cast_shadows>1</cast_shadows>
      </visual>
      <collision name='base_link_collision'>
        <laser_retro>0</laser_retro>
        <max_contacts>10</max_contacts>
        <pose frame=''>0 0 0 0 -0 0</pose>
        <geometry>
          <cylinder>
            <radius>0.11</radius>
            <length>0.06</length>
          </cylinder>
        </geometry>
        <surface>
          <friction>
            <ode>
              <mu>1</mu>
              <mu2>1</mu2>
              <fdir1>0 0 0</fdir1>
              <slip1>0</slip1>
              <slip2>0</slip2>
            </ode>
            <torsional>
              <coefficient>1</coefficient>
              <patch_radius>0</patch_radius>
              <surface_radius>0</surface_radius>
              <use_patch_radius>1</use_patch_radius>
              <ode>
                <slip>0</slip>
              </ode>
            </torsional>
          </friction>
          <bounce>
            <restitution_coefficient>0</restitution_coefficient>
            <threshold>1e+06</threshold>
          </bounce>
          <contact>
            <collide_without_contact>0</collide_without_contact>
            <collide_without_contact_bitmask>1</collide_without_contact_bitmask>
            <collide_bitmask>1</collide_bitmask>
            <ode>
              <soft_cfm>0</soft_cfm>
              <soft_erp>0.2</soft_erp>
              <kp>1e+13</kp>
              <kd>1</kd>
              <max_vel>0</max_vel>
              <min_depth>0.001</min_depth>
            </ode>
            <bullet>
              <split_impulse>1</split_impulse>
              <split_impulse_penetration_threshold>-0.01</split_impulse_penetration_threshold>
              <soft_cfm>0</soft_cfm>
              <soft_erp>0.2</soft_erp>
              <kp>1e+13</kp>
              <kd>1</kd>
            </bullet>
          </contact>
        </surface>
      </collision>
    </link>
    <link name='cgo3_camera_link'>
      <inertial>
        <pose frame=''>-0.041 0 -0.045 0 -0 0</pose>
        <mass>0.1</mass>
        <inertia>
          <ixx>0.001</ixx>
          <ixy>0</ixy>
          <ixz>0</ixz>
          <iyy>0.001</iyy>
          <iyz>0</iyz>
          <izz>0.001</izz>
        </inertia>
      </inertial>
      <sensor name='camera_imu' type='imu'>
        <always_on>1</always_on>
        <imu/>
      </sensor>
      <sensor name='camera' type='camera'>
        <pose frame=''>-0.041 -0.009 -0.045 0 -0 3.14159</pose>
        <camera name='__default__'>
          <horizontal_fov>2</horizontal_fov>
          <image>
            <format>R8G8B8</format>
            <width>640</width>
            <height>360</height>
          </image>
          <clip>
            <near>0.05</near>
            <far>15000</far>
          </clip>
        </camera>
        <always_on>1</always_on>
        <update_rate>10</update_rate>
        <visualize>1</visualize>
        <plugin name='GstCameraPlugin' filename='libgazebo_gst_camera_plugin.so'>
          <robotNamespace/>
          <udpHost>127.0.0.1</udpHost>
          <udpPort>5600</udpPort>
        </plugin>
        <plugin name="CameraManagerPlugin" filename="libgazebo_camera_manager_plugin.so">
            <robotNamespace>typhoon_h480</robotNamespace>
            <interval>1</interval>
            <width>3840</width>
            <height>2160</height>
            <maximum_zoom>8.0</maximum_zoom>
            <video_uri>5600</video_uri>
            <system_id>1</system_id>
            <cam_component_id>100</cam_component_id>
            <mavlink_cam_udp_port>14530</mavlink_cam_udp_port>
        </plugin>
        <plugin name='GeotaggedImagesPlugin' filename='libgazebo_geotagged_images_plugin.so'>
          <robotNamespace>typhoon_h480</robotNamespace>
          <interval>1</interval>
          <width>3840</width>
          <height>2160</height>
          <maximum_zoom>8.0</maximum_zoom>
        </plugin>
      </sensor>
      <self_collide>0</self_collide>
      <enable_wind>0</enable_wind>
      <kinematic>0</kinematic>
      <pose frame=''>0 0 0.123727 0 -0 0</pose>
      <gravity>1</gravity>
      <visual name='cgo3_camera_visual'>
        <pose frame=''>0 0 0.05 0 -0 0</pose>
        <geometry>
          <mesh>
            <scale>0.001 0.001 0.001</scale>
            <uri>model://ral_x6/meshes/camera_sony_qx1_gimbal.stl</uri>
          </mesh>
        </geometry>
        <material>
          <script>
            <name>Gazebo/DarkGrey</name>
            <uri>file://media/materials/scripts/gazebo.material</uri>
          </script>
          <shader type='pixel'>
            <normal_map>__default__</normal_map>
          </shader>
          <ambient>0.175 0.175 0.175 1</ambient>
          <diffuse>0.175 0.175 0.175 1</diffuse>
          <specular>0.175 0.175 0.175 1</specular>
          <emissive>0 0 0 1</emissive>
        </material>
        <transparency>0</transparency>
        <cast_shadows>1</cast_shadows>
      </visual>
      <collision name='cgo3_camera_collision'>
        <laser_retro>0</laser_retro>
        <max_contacts>10</max_contacts>
        <pose frame=''>-0.041 -0.0075 -0.046 0 -0 0</pose>
        <geometry>
          <sphere>
            <radius>0.015</radius>
          </sphere>
        </geometry>
        <surface>
          <friction>
            <ode>
              <mu>1</mu>
              <mu2>1</mu2>
              <fdir1>0 0 0</fdir1>
              <slip1>0</slip1>
              <slip2>0</slip2>
            </ode>
            <torsional>
              <coefficient>1</coefficient>
              <patch_radius>0</patch_radius>
              <surface_radius>0</surface_radius>
              <use_patch_radius>1</use_patch_radius>
              <ode>
                <slip>0</slip>
              </ode>
            </torsional>
          </friction>
          <bounce>
            <restitution_coefficient>0</restitution_coefficient>
            <threshold>1e+06</threshold>
          </bounce>
          <contact>
            <collide_without_contact>0</collide_without_contact>
            <collide_without_contact_bitmask>1</collide_without_contact_bitmask>
            <collide_bitmask>1</collide_bitmask>
            <ode>
              <soft_cfm>0</soft_cfm>
              <soft_erp>0.2</soft_erp>
              <kp>1e+08</kp>
              <kd>1</kd>
              <max_vel>0.01</max_vel>
              <min_depth>0.001</min_depth>
            </ode>
            <bullet>
              <split_impulse>1</split_impulse>
              <split_impulse_penetration_threshold>-0.01</split_impulse_penetration_threshold>
              <soft_cfm>0</soft_cfm>
              <soft_erp>0.2</soft_erp>
              <kp>1e+08</kp>
              <kd>1</kd>
            </bullet>
          </contact>
        </surface>
      </collision>
    </link>

    <link name='cgo3_horizontal_arm_link'>
      <inertial>
        <pose frame=''>-0.041 0 -0.081 0 -0 0</pose>
        <mass>0.1</mass>
        <inertia>
          <ixx>0.001</ixx>
          <ixy>0</ixy>
          <ixz>0</ixz>
          <iyy>0.001</iyy>
          <iyz>0</iyz>
          <izz>0.001</izz>
        </inertia>
      </inertial>
      <self_collide>0</self_collide>
      <enable_wind>0</enable_wind>
      <kinematic>0</kinematic>
      <pose frame=''>0 0 0.173727 0 -0 0</pose>
      <gravity>1</gravity>
      <visual name='cgo3_horizontal_arm_visual'>
        <pose frame=''>0 0 0 0 -0 0</pose>
        <geometry>
          <mesh>
            <scale>0.001 0.001 0.001</scale>
            <uri>model://ral_x6/meshes/stab_1.stl</uri>
          </mesh>
        </geometry>
        <material>
          <script>
            <name>Gazebo/DarkGrey</name>
            <uri>file://media/materials/scripts/gazebo.material</uri>
          </script>
          <shader type='pixel'>
            <normal_map>__default__</normal_map>
          </shader>
          <ambient>0.175 0.175 0.175 1</ambient>
          <diffuse>0.175 0.175 0.175 1</diffuse>
          <specular>0.175 0.175 0.175 1</specular>
          <emissive>0 0 0 1</emissive>
        </material>
        <transparency>0</transparency>
        <cast_shadows>1</cast_shadows>
      </visual>
    </link>

    <link name='cgo3_mount_link'>
      <inertial>
        <pose frame=''>-0.041 0 -0.162 0 -0 0</pose>
        <mass>0.1</mass>
        <inertia>
          <ixx>0.001</ixx>
          <ixy>0</ixy>
          <ixz>0</ixz>
          <iyy>0.001</iyy>
          <iyz>0</iyz>
          <izz>0.001</izz>
        </inertia>
      </inertial>
      <self_collide>0</self_collide>
      <enable_wind>0</enable_wind>
      <kinematic>0</kinematic>
      <pose frame=''>0 0 0.173727 0 -0 0</pose>
      <gravity>1</gravity>
      <visual name='cgo3_mount_visual'>
        <pose frame=''>0 0 0 0 -0 0</pose>
        <geometry>
          <mesh>
            <scale>0.001 0.001 0.001</scale>
            <uri>model://ral_x6/meshes/stab_3.stl</uri>
          </mesh>
        </geometry>
        <material>
          <script>
            <name>Gazebo/DarkGrey</name>
            <uri>file://media/materials/scripts/gazebo.material</uri>
          </script>
          <shader type='pixel'>
            <normal_map>__default__</normal_map>
          </shader>
          <ambient>0.175 0.175 0.175 1</ambient>
          <diffuse>0.175 0.175 0.175 1</diffuse>
          <specular>0.175 0.175 0.175 1</specular>
          <emissive>0 0 0 1</emissive>
        </material>
        <transparency>0</transparency>
        <cast_shadows>1</cast_shadows>
      </visual>
    </link>

    <link name='cgo3_vertical_arm_link'>
      <inertial>
        <pose frame=''>-0.041 0 -0.162 0 -0 0</pose>
        <mass>0.1</mass>
        <inertia>
          <ixx>0.001</ixx>
          <ixy>0</ixy>
          <ixz>0</ixz>
          <iyy>0.001</iyy>
          <iyz>0</iyz>
          <izz>0.001</izz>
        </inertia>
      </inertial>
      <self_collide>0</self_collide>
      <enable_wind>0</enable_wind>
      <kinematic>0</kinematic>
      <pose frame=''>0 0 0.173727 0 -0 0</pose>
      <gravity>1</gravity>
      <visual name='cgo3_vertical_arm_visual'>
        <pose frame=''>0 0 0 0 -0 0</pose>
        <geometry>
          <mesh>
            <scale>0.001 0.001 0.001</scale>
            <uri>model://ral_x6/meshes/stab_2.stl</uri>
          </mesh>
        </geometry>
        <material>
          <script>
            <name>Gazebo/DarkGrey</name>
            <uri>file://media/materials/scripts/gazebo.material</uri>
          </script>
          <shader type='pixel'>
            <normal_map>__default__</normal_map>
          </shader>
          <ambient>0.175 0.175 0.175 1</ambient>
          <diffuse>0.175 0.175 0.175 1</diffuse>
          <specular>0.175 0.175 0.175 1</specular>
          <emissive>0 0 0 1</emissive>
        </material>
        <transparency>0</transparency>
        <cast_shadows>1</cast_shadows>
      </visual>
    </link>

    <link name='leg_1'>
      <inertial>
        <mass>1</mass>
        <inertia>
          <ixx>0.145833</ixx>
          <ixy>0</ixy>
          <ixz>0</ixz>
          <iyy>0.145833</iyy>
          <iyz>0</iyz>
          <izz>0.125</izz>
        </inertia>
        <pose frame=''>0 0 0 0 -0 0</pose>
      </inertial>
      <pose frame=''>-0.000621 -0.082256 0.179789 0 -0 0</pose>
      <gravity>1</gravity>
      <self_collide>0</self_collide>
      <kinematic>0</kinematic>
      <enable_wind>0</enable_wind>
      <collision name='collision'>
        <laser_retro>0</laser_retro>
        <max_contacts>10</max_contacts>
        <pose frame=''>0.001 -0.03 -0.08 -0.36 0 0</pose>
        <geometry>
          <cylinder>
            <radius>0.005</radius>
            <length>0.17</length>
          </cylinder>
        </geometry>
        <surface>
          <friction>
            <ode>
              <mu>1</mu>
              <mu2>1</mu2>
              <fdir1>0 0 0</fdir1>
              <slip1>0</slip1>
              <slip2>0</slip2>
            </ode>
            <torsional>
              <coefficient>1</coefficient>
              <patch_radius>0</patch_radius>
              <surface_radius>0</surface_radius>
              <use_patch_radius>1</use_patch_radius>
              <ode>
                <slip>0</slip>
              </ode>
            </torsional>
          </friction>
          <bounce>
            <restitution_coefficient>0</restitution_coefficient>
            <threshold>1e+06</threshold>
          </bounce>
          <contact>
            <collide_without_contact>0</collide_without_contact>
            <collide_without_contact_bitmask>1</collide_without_contact_bitmask>
            <collide_bitmask>1</collide_bitmask>
            <ode>
              <soft_cfm>0</soft_cfm>
              <soft_erp>0.2</soft_erp>
              <kp>1e+13</kp>
              <kd>1</kd>
              <max_vel>0.01</max_vel>
              <min_depth>0</min_depth>
            </ode>
            <bullet>
              <split_impulse>1</split_impulse>
              <split_impulse_penetration_threshold>-0.01</split_impulse_penetration_threshold>
              <soft_cfm>0</soft_cfm>
              <soft_erp>0.2</soft_erp>
              <kp>1e+13</kp>
              <kd>1</kd>
            </bullet>
          </contact>
        </surface>
      </collision>
      <collision name='collision_1'>
        <laser_retro>0</laser_retro>
        <max_contacts>10</max_contacts>
        <pose frame=''>0.001 -0.063 -0.175 0 1.57 0</pose>
        <geometry>
          <cylinder>
            <radius>0.006</radius>
            <length>0.255</length>
          </cylinder>
        </geometry>
        <surface>
          <friction>
            <ode>
              <mu>1</mu>
              <mu2>1</mu2>
              <fdir1>0 0 0</fdir1>
              <slip1>0</slip1>
              <slip2>0</slip2>
            </ode>
            <torsional>
              <coefficient>1</coefficient>
              <patch_radius>0</patch_radius>
              <surface_radius>0</surface_radius>
              <use_patch_radius>1</use_patch_radius>
              <ode>
                <slip>0</slip>
              </ode>
            </torsional>
          </friction>
          <bounce>
            <restitution_coefficient>0</restitution_coefficient>
            <threshold>1e+06</threshold>
          </bounce>
          <contact>
            <collide_without_contact>0</collide_without_contact>
            <collide_without_contact_bitmask>1</collide_without_contact_bitmask>
            <collide_bitmask>1</collide_bitmask>
            <ode>
              <soft_cfm>0</soft_cfm>
              <soft_erp>0.2</soft_erp>
              <kp>1e+13</kp>
              <kd>1</kd>
              <max_vel>0.01</max_vel>
              <min_depth>0</min_depth>
            </ode>
            <bullet>
              <split_impulse>1</split_impulse>
              <split_impulse_penetration_threshold>-0.01</split_impulse_penetration_threshold>
              <soft_cfm>0</soft_cfm>
              <soft_erp>0.2</soft_erp>
              <kp>1e+13</kp>
              <kd>1</kd>
            </bullet>
          </contact>
        </surface>
      </collision>
    </link>

    <link name='leg_2'>
      <inertial>
        <mass>1</mass>
        <inertia>
          <ixx>0.145833</ixx>
          <ixy>0</ixy>
          <ixz>0</ixz>
          <iyy>0.145833</iyy>
          <iyz>0</iyz>
          <izz>0.125</izz>
        </inertia>
        <pose frame=''>0 0 0 0 -0 0</pose>
      </inertial>
      <pose frame=''>-0.000621 0.082256 0.179789 0 -0 0</pose>
      <gravity>1</gravity>
      <self_collide>0</self_collide>
      <kinematic>0</kinematic>
      <enable_wind>0</enable_wind>
      <collision name='collision_1'>
        <laser_retro>0</laser_retro>
        <max_contacts>10</max_contacts>
        <pose frame=''>0.001 0.063 -0.175 0 1.57 0</pose>
        <geometry>
          <cylinder>
            <radius>0.006</radius>
            <length>0.255</length>
          </cylinder>
        </geometry>
        <surface>
          <friction>
            <ode>
              <mu>1</mu>
              <mu2>1</mu2>
              <fdir1>0 0 0</fdir1>
              <slip1>0</slip1>
              <slip2>0</slip2>
            </ode>
            <torsional>
              <coefficient>1</coefficient>
              <patch_radius>0</patch_radius>
              <surface_radius>0</surface_radius>
              <use_patch_radius>1</use_patch_radius>
              <ode>
                <slip>0</slip>
              </ode>
            </torsional>
          </friction>
          <bounce>
            <restitution_coefficient>0</restitution_coefficient>
            <threshold>1e+06</threshold>
          </bounce>
          <contact>
            <collide_without_contact>0</collide_without_contact>
            <collide_without_contact_bitmask>1</collide_without_contact_bitmask>
            <collide_bitmask>1</collide_bitmask>
            <ode>
              <soft_cfm>0</soft_cfm>
              <soft_erp>0.2</soft_erp>
              <kp>1e+13</kp>
              <kd>1</kd>
              <max_vel>0.01</max_vel>
              <min_depth>0</min_depth>
            </ode>
            <bullet>
              <split_impulse>1</split_impulse>
              <split_impulse_penetration_threshold>-0.01</split_impulse_penetration_threshold>
              <soft_cfm>0</soft_cfm>
              <soft_erp>0.2</soft_erp>
              <kp>1e+13</kp>
              <kd>1</kd>
            </bullet>
          </contact>
        </surface>
      </collision>
      <collision name='collision'>
        <laser_retro>0</laser_retro>
        <max_contacts>10</max_contacts>
        <pose frame=''>0.001 0.03 -0.08 0.36 -0 0</pose>
        <geometry>
          <cylinder>
            <radius>0.005</radius>
            <length>0.17</length>
          </cylinder>
        </geometry>
        <surface>
          <friction>
            <ode>
              <mu>1</mu>
              <mu2>1</mu2>
              <fdir1>0 0 0</fdir1>
              <slip1>0</slip1>
              <slip2>0</slip2>
            </ode>
            <torsional>
              <coefficient>1</coefficient>
              <patch_radius>0</patch_radius>
              <surface_radius>0</surface_radius>
              <use_patch_radius>1</use_patch_radius>
              <ode>
                <slip>0</slip>
              </ode>
            </torsional>
          </friction>
          <bounce>
            <restitution_coefficient>0</restitution_coefficient>
            <threshold>1e+06</threshold>
          </bounce>
          <contact>
            <collide_without_contact>0</collide_without_contact>
            <collide_without_contact_bitmask>1</collide_without_contact_bitmask>
            <collide_bitmask>1</collide_bitmask>
            <ode>
              <soft_cfm>0</soft_cfm>
              <soft_erp>0.2</soft_erp>
              <kp>1e+13</kp>
              <kd>1</kd>
              <max_vel>0.01</max_vel>
              <min_depth>0</min_depth>
            </ode>
            <bullet>
              <split_impulse>1</split_impulse>
              <split_impulse_penetration_threshold>-0.01</split_impulse_penetration_threshold>
              <soft_cfm>0</soft_cfm>
              <soft_erp>0.2</soft_erp>
              <kp>1e+13</kp>
              <kd>1</kd>
            </bullet>
          </contact>
        </surface>
      </collision>
    </link>

    <link name='rotor_0'>
      <pose frame=''>-0.209396 0.122762 0.182219 0 -0 2.0944</pose>
      <inertial>
        <pose frame=''>0 0 0 0 -0 0</pose>
        <mass>0.005</mass>
        <inertia>
          <ixx>9.7e-07</ixx>
          <ixy>0</ixy>
          <ixz>0</ixz>
          <iyy>0.0002731</iyy>
          <iyz>0</iyz>
          <izz>0.000274</izz>
        </inertia>
      </inertial>
      <gravity>1</gravity>
      <velocity_decay/>
      <self_collide>0</self_collide>
      <enable_wind>0</enable_wind>
      <kinematic>0</kinematic>
      <visual name='rotor_0_visual'>
        <pose frame=''>-0.211396 -0.119762 -0.009 0 -0 0</pose>
        <geometry>
          <mesh>
            <scale>0.001 0.001 0.001</scale>
            <uri>model://ral_x6/meshes/prop_17x55_ccw_v2.stl</uri>
          </mesh>
        </geometry>
        <material>
          <script>
            <name>Gazebo/Blue</name>
            <uri>file://media/materials/scripts/gazebo.material</uri>
          </script>
          <shader type='pixel'>
            <normal_map>__default__</normal_map>
          </shader>
          <ambient>0 0 1 1</ambient>
          <diffuse>0 0 1 1</diffuse>
          <specular>0.1 0.1 0.1 1</specular>
          <emissive>0 0 0 1</emissive>
        </material>
        <transparency>0</transparency>
        <cast_shadows>1</cast_shadows>
      </visual>
      <collision name='rotor_0_collision'>
        <laser_retro>0</laser_retro>
        <max_contacts>10</max_contacts>
        <pose frame=''>0 -0.01 0.019 0 -0 0</pose>
        <geometry>
          <cylinder>
            <radius>0.108</radius>
            <length>0.005</length>
          </cylinder>
        </geometry>
        <surface>
          <friction>
            <ode>
              <mu>1</mu>
              <mu2>1</mu2>
              <fdir1>0 0 0</fdir1>
              <slip1>0</slip1>
              <slip2>0</slip2>
            </ode>
            <torsional>
              <coefficient>1</coefficient>
              <patch_radius>0</patch_radius>
              <surface_radius>0</surface_radius>
              <use_patch_radius>1</use_patch_radius>
              <ode>
                <slip>0</slip>
              </ode>
            </torsional>
          </friction>
          <bounce>
            <restitution_coefficient>0</restitution_coefficient>
            <threshold>1e+06</threshold>
          </bounce>
          <contact>
            <collide_without_contact>0</collide_without_contact>
            <collide_without_contact_bitmask>1</collide_without_contact_bitmask>
            <collide_bitmask>1</collide_bitmask>
            <ode>
              <soft_cfm>0</soft_cfm>
              <soft_erp>0.2</soft_erp>
              <kp>1e+13</kp>
              <kd>1</kd>
              <max_vel>0.01</max_vel>
              <min_depth>0</min_depth>
            </ode>
            <bullet>
              <split_impulse>1</split_impulse>
              <split_impulse_penetration_threshold>-0.01</split_impulse_penetration_threshold>
              <soft_cfm>0</soft_cfm>
              <soft_erp>0.2</soft_erp>
              <kp>1e+13</kp>
              <kd>1</kd>
            </bullet>
          </contact>
        </surface>
      </collision>
    </link>

    <link name='rotor_1'>
      <pose frame=''>0.2109 -0.11911 0.182219 0 0 -2.0944</pose>
      <inertial>
        <pose frame=''>0 0 0 0 -0 0</pose>
        <mass>0.005</mass>
        <inertia>
          <ixx>9.7e-07</ixx>
          <ixy>0</ixy>
          <ixz>0</ixz>
          <iyy>0.0002731</iyy>
          <iyz>0</iyz>
          <izz>0.000274</izz>
        </inertia>
      </inertial>
      <gravity>1</gravity>
      <velocity_decay/>
      <self_collide>0</self_collide>
      <enable_wind>0</enable_wind>
      <kinematic>0</kinematic>
      <visual name='rotor_1_visual'>
        <pose frame=''>0.000399 -0.243300 -0.009 0 -0 0</pose>
        <geometry>
          <mesh>
            <scale>0.001 0.001 0.001</scale>
            <uri>model://ral_x6/meshes/prop_17x55_cw_v2.stl</uri>
          </mesh>
        </geometry>
        <material>
          <script>
            <name>Gazebo/DarkGrey</name>
            <uri>file://media/materials/scripts/gazebo.material</uri>
          </script>
          <shader type='pixel'>
            <normal_map>__default__</normal_map>
          </shader>
          <ambient>0.175 0.175 0.175 1</ambient>
          <diffuse>0.175 0.175 0.175 1</diffuse>
          <specular>0.175 0.175 0.175 1</specular>
          <emissive>0 0 0 1</emissive>
        </material>
        <transparency>0</transparency>
        <cast_shadows>1</cast_shadows>
      </visual>
      <collision name='rotor_1_collision'>
        <laser_retro>0</laser_retro>
        <max_contacts>10</max_contacts>
        <pose frame=''>0 0 0.019 0 -0 0</pose>
        <geometry>
          <cylinder>
            <radius>0.108</radius>
            <length>0.005</length>
          </cylinder>
        </geometry>
        <surface>
          <friction>
            <ode>
              <mu>1</mu>
              <mu2>1</mu2>
              <fdir1>0 0 0</fdir1>
              <slip1>0</slip1>
              <slip2>0</slip2>
            </ode>
            <torsional>
              <coefficient>1</coefficient>
              <patch_radius>0</patch_radius>
              <surface_radius>0</surface_radius>
              <use_patch_radius>1</use_patch_radius>
              <ode>
                <slip>0</slip>
              </ode>
            </torsional>
          </friction>
          <bounce>
            <restitution_coefficient>0</restitution_coefficient>
            <threshold>1e+06</threshold>
          </bounce>
          <contact>
            <collide_without_contact>0</collide_without_contact>
            <collide_without_contact_bitmask>1</collide_without_contact_bitmask>
            <collide_bitmask>1</collide_bitmask>
            <ode>
              <soft_cfm>0</soft_cfm>
              <soft_erp>0.2</soft_erp>
              <kp>1e+13</kp>
              <kd>1</kd>
              <max_vel>0.01</max_vel>
              <min_depth>0</min_depth>
            </ode>
            <bullet>
              <split_impulse>1</split_impulse>
              <split_impulse_penetration_threshold>-0.01</split_impulse_penetration_threshold>
              <soft_cfm>0</soft_cfm>
              <soft_erp>0.2</soft_erp>
              <kp>1e+13</kp>
              <kd>1</kd>
            </bullet>
          </contact>
        </surface>
      </collision>
    </link>

    <link name='rotor_2'>
      <pose frame=''>-0.209396 -0.122762 0.182219 0 -0 2.0944</pose>
      <inertial>
        <pose frame=''>0 0 0 0 -0 0</pose>
        <mass>0.005</mass>
        <inertia>
          <ixx>9.7e-07</ixx>
          <ixy>0</ixy>
          <ixz>0</ixz>
          <iyy>0.0002731</iyy>
          <iyz>0</iyz>
          <izz>0.000274</izz>
        </inertia>
      </inertial>
      <gravity>1</gravity>
      <velocity_decay/>
      <self_collide>0</self_collide>
      <enable_wind>0</enable_wind>
      <kinematic>0</kinematic>
      <visual name='rotor_2_visual'>
        <pose frame=''>0.001879 -0.242705 -0.009 0 -0 0</pose>
        <geometry>
          <mesh>
            <scale>0.001 0.001 0.001</scale>
            <uri>model://ral_x6/meshes/prop_17x55_cw_v2.stl</uri>
          </mesh>
        </geometry>
        <material>
          <script>
            <name>Gazebo/DarkGrey</name>
            <uri>file://media/materials/scripts/gazebo.material</uri>
          </script>
          <shader type='pixel'>
            <normal_map>__default__</normal_map>
          </shader>
          <ambient>0.175 0.175 0.175 1</ambient>
          <diffuse>0.175 0.175 0.175 1</diffuse>
          <specular>0.175 0.175 0.175 1</specular>
          <emissive>0 0 0 1</emissive>
        </material>
        <transparency>0</transparency>
        <cast_shadows>1</cast_shadows>
      </visual>
      <collision name='rotor_2_collision'>
        <laser_retro>0</laser_retro>
        <max_contacts>10</max_contacts>
        <pose frame=''>0 0 0.019 0 -0 0</pose>
        <geometry>
          <cylinder>
            <radius>0.108</radius>
            <length>0.005</length>
          </cylinder>
        </geometry>
        <surface>
          <friction>
            <ode>
              <mu>1</mu>
              <mu2>1</mu2>
              <fdir1>0 0 0</fdir1>
              <slip1>0</slip1>
              <slip2>0</slip2>
            </ode>
            <torsional>
              <coefficient>1</coefficient>
              <patch_radius>0</patch_radius>
              <surface_radius>0</surface_radius>
              <use_patch_radius>1</use_patch_radius>
              <ode>
                <slip>0</slip>
              </ode>
            </torsional>
          </friction>
          <bounce>
            <restitution_coefficient>0</restitution_coefficient>
            <threshold>1e+06</threshold>
          </bounce>
          <contact>
            <collide_without_contact>0</collide_without_contact>
            <collide_without_contact_bitmask>1</collide_without_contact_bitmask>
            <collide_bitmask>1</collide_bitmask>
            <ode>
              <soft_cfm>0</soft_cfm>
              <soft_erp>0.2</soft_erp>
              <kp>1e+13</kp>
              <kd>1</kd>
              <max_vel>0.01</max_vel>
              <min_depth>0</min_depth>
            </ode>
            <bullet>
              <split_impulse>1</split_impulse>
              <split_impulse_penetration_threshold>-0.01</split_impulse_penetration_threshold>
              <soft_cfm>0</soft_cfm>
              <soft_erp>0.2</soft_erp>
              <kp>1e+13</kp>
              <kd>1</kd>
            </bullet>
          </contact>
        </surface>
      </collision>
    </link>

    <link name='rotor_3'>
      <pose frame=''>0.211396 0.119762 0.182219 0 -0 0</pose>
      <inertial>
        <pose frame=''>0 0 0 0 -0 0</pose>
        <mass>0.005</mass>
        <inertia>
          <ixx>9.7e-07</ixx>
          <ixy>0</ixy>
          <ixz>0</ixz>
          <iyy>0.0002731</iyy>
          <iyz>0</iyz>
          <izz>0.000274</izz>
        </inertia>
      </inertial>
      <gravity>1</gravity>
      <velocity_decay/>
      <self_collide>0</self_collide>
      <enable_wind>0</enable_wind>
      <kinematic>0</kinematic>
      <visual name='rotor_3_visual'>
        <pose frame=''>-0.211396 -0.119762 -0.009 0 -0 0</pose>
        <geometry>
          <mesh>
            <scale>0.001 0.001 0.001</scale>
            <uri>model://ral_x6/meshes/prop_17x55_ccw_v2.stl</uri>
          </mesh>
        </geometry>
        <material>
          <script>
            <name>Gazebo/Blue</name>
            <uri>file://media/materials/scripts/gazebo.material</uri>
          </script>
          <shader type='pixel'>
            <normal_map>__default__</normal_map>
          </shader>
          <ambient>0 0 1 1</ambient>
          <diffuse>0 0 1 1</diffuse>
          <specular>0.1 0.1 0.1 1</specular>
          <emissive>0 0 0 1</emissive>
        </material>
        <transparency>0</transparency>
        <cast_shadows>1</cast_shadows>
      </visual>
      <collision name='rotor_3_collision'>
        <laser_retro>0</laser_retro>
        <max_contacts>10</max_contacts>
        <pose frame=''>0 0 0.019 0 -0 0</pose>
        <geometry>
          <cylinder>
            <radius>0.108</radius>
            <length>0.005</length>
          </cylinder>
        </geometry>
        <surface>
          <friction>
            <ode>
              <mu>1</mu>
              <mu2>1</mu2>
              <fdir1>0 0 0</fdir1>
              <slip1>0</slip1>
              <slip2>0</slip2>
            </ode>
            <torsional>
              <coefficient>1</coefficient>
              <patch_radius>0</patch_radius>
              <surface_radius>0</surface_radius>
              <use_patch_radius>1</use_patch_radius>
              <ode>
                <slip>0</slip>
              </ode>
            </torsional>
          </friction>
          <bounce>
            <restitution_coefficient>0</restitution_coefficient>
            <threshold>1e+06</threshold>
          </bounce>
          <contact>
            <collide_without_contact>0</collide_without_contact>
            <collide_without_contact_bitmask>1</collide_without_contact_bitmask>
            <collide_bitmask>1</collide_bitmask>
            <ode>
              <soft_cfm>0</soft_cfm>
              <soft_erp>0.2</soft_erp>
              <kp>1e+13</kp>
              <kd>1</kd>
              <max_vel>0.01</max_vel>
              <min_depth>0</min_depth>
            </ode>
            <bullet>
              <split_impulse>1</split_impulse>
              <split_impulse_penetration_threshold>-0.01</split_impulse_penetration_threshold>
              <soft_cfm>0</soft_cfm>
              <soft_erp>0.2</soft_erp>
              <kp>1e+13</kp>
              <kd>1</kd>
            </bullet>
          </contact>
        </surface>
      </collision>
    </link>

    <link name='rotor_4'>
      <pose frame=''>-0.001879 0.242705 0.182219 0 -0 0</pose>
      <inertial>
        <pose frame=''>0 0 0 0 -0 0</pose>
        <mass>0.005</mass>
        <inertia>
          <ixx>9.7e-07</ixx>
          <ixy>0</ixy>
          <ixz>0</ixz>
          <iyy>0.0002731</iyy>
          <iyz>0</iyz>
          <izz>0.000274</izz>
        </inertia>
      </inertial>
      <gravity>1</gravity>
      <velocity_decay/>
      <self_collide>0</self_collide>
      <enable_wind>0</enable_wind>
      <kinematic>0</kinematic>
      <visual name='rotor_4_visual'>
        <pose frame=''>0.001879 -0.242705 -0.009 0 -0 0</pose>
        <geometry>
          <mesh>
            <scale>0.001 0.001 0.001</scale>
            <uri>model://ral_x6/meshes/prop_17x55_cw_v2.stl</uri>
          </mesh>
        </geometry>
        <material>
          <script>
            <name>Gazebo/DarkGrey</name>
            <uri>file://media/materials/scripts/gazebo.material</uri>
          </script>
          <shader type='pixel'>
            <normal_map>__default__</normal_map>
          </shader>
          <ambient>0.175 0.175 0.175 1</ambient>
          <diffuse>0.175 0.175 0.175 1</diffuse>
          <specular>0.175 0.175 0.175 1</specular>
          <emissive>0 0 0 1</emissive>
        </material>
        <transparency>0</transparency>
        <cast_shadows>1</cast_shadows>
      </visual>
      <collision name='rotor_4_collision'>
        <laser_retro>0</laser_retro>
        <max_contacts>10</max_contacts>
        <pose frame=''>0 0 0.019 0 -0 0</pose>
        <geometry>
          <cylinder>
            <radius>0.108</radius>
            <length>0.005</length>
          </cylinder>
        </geometry>
        <surface>
          <friction>
            <ode>
              <mu>1</mu>
              <mu2>1</mu2>
              <fdir1>0 0 0</fdir1>
              <slip1>0</slip1>
              <slip2>0</slip2>
            </ode>
            <torsional>
              <coefficient>1</coefficient>
              <patch_radius>0</patch_radius>
              <surface_radius>0</surface_radius>
              <use_patch_radius>1</use_patch_radius>
              <ode>
                <slip>0</slip>
              </ode>
            </torsional>
          </friction>
          <bounce>
            <restitution_coefficient>0</restitution_coefficient>
            <threshold>1e+06</threshold>
          </bounce>
          <contact>
            <collide_without_contact>0</collide_without_contact>
            <collide_without_contact_bitmask>1</collide_without_contact_bitmask>
            <collide_bitmask>1</collide_bitmask>
            <ode>
              <soft_cfm>0</soft_cfm>
              <soft_erp>0.2</soft_erp>
              <kp>1e+13</kp>
              <kd>1</kd>
              <max_vel>0.01</max_vel>
              <min_depth>0</min_depth>
            </ode>
            <bullet>
              <split_impulse>1</split_impulse>
              <split_impulse_penetration_threshold>-0.01</split_impulse_penetration_threshold>
              <soft_cfm>0</soft_cfm>
              <soft_erp>0.2</soft_erp>
              <kp>1e+13</kp>
              <kd>1</kd>
            </bullet>
          </contact>
        </surface>
      </collision>
    </link>

    <link name='rotor_5'>
      <pose frame=''>-0.001644 -0.242283 0.182219 0 0 -2.0944</pose>
      <inertial>
        <pose frame=''>0 0 0 0 -0 0</pose>
        <mass>0.005</mass>
        <inertia>
          <ixx>9.7e-07</ixx>
          <ixy>0</ixy>
          <ixz>0</ixz>
          <iyy>0.0002731</iyy>
          <iyz>0</iyz>
          <izz>0.000274</izz>
        </inertia>
      </inertial>
      <gravity>1</gravity>
      <velocity_decay/>
      <self_collide>0</self_collide>
      <enable_wind>0</enable_wind>
      <kinematic>0</kinematic>
      <visual name='rotor_5_visual'>
        <pose frame=''>-0.211396 -0.119762 -0.009 0 -0 0</pose>
        <geometry>
          <mesh>
            <scale>0.001 0.001 0.001</scale>
            <uri>model://ral_x6/meshes/prop_17x55_ccw_v2.stl</uri>
          </mesh>
        </geometry>
        <material>
          <script>
            <name>Gazebo/Blue</name>
            <uri>file://media/materials/scripts/gazebo.material</uri>
          </script>
          <shader type='pixel'>
            <normal_map>__default__</normal_map>
          </shader>
          <ambient>0 0 1 1</ambient>
          <diffuse>0 0 1 1</diffuse>
          <specular>0.1 0.1 0.1 1</specular>
          <emissive>0 0 0 1</emissive>
        </material>
        <transparency>0</transparency>
        <cast_shadows>1</cast_shadows>
      </visual>
      <collision name='rotor_5_collision'>
        <laser_retro>0</laser_retro>
        <max_contacts>10</max_contacts>
        <pose frame=''>0 0 0.019 0 -0 0</pose>
        <geometry>
          <cylinder>
            <radius>0.108</radius>
            <length>0.005</length>
          </cylinder>
        </geometry>
        <surface>
          <friction>
            <ode>
              <mu>1</mu>
              <mu2>1</mu2>
              <fdir1>0 0 0</fdir1>
              <slip1>0</slip1>
              <slip2>0</slip2>
            </ode>
            <torsional>
              <coefficient>1</coefficient>
              <patch_radius>0</patch_radius>
              <surface_radius>0</surface_radius>
              <use_patch_radius>1</use_patch_radius>
              <ode>
                <slip>0</slip>
              </ode>
            </torsional>
          </friction>
          <bounce>
            <restitution_coefficient>0</restitution_coefficient>
            <threshold>1e+06</threshold>
          </bounce>
          <contact>
            <collide_without_contact>0</collide_without_contact>
            <collide_without_contact_bitmask>1</collide_without_contact_bitmask>
            <collide_bitmask>1</collide_bitmask>
            <ode>
              <soft_cfm>0</soft_cfm>
              <soft_erp>0.2</soft_erp>
              <kp>1e+13</kp>
              <kd>1</kd>
              <max_vel>0.01</max_vel>
              <min_depth>0</min_depth>
            </ode>
            <bullet>
              <split_impulse>1</split_impulse>
              <split_impulse_penetration_threshold>-0.01</split_impulse_penetration_threshold>
              <soft_cfm>0</soft_cfm>
              <soft_erp>0.2</soft_erp>
              <kp>1e+13</kp>
              <kd>1</kd>
            </bullet>
          </contact>
        </surface>
      </collision>
    </link>

    <link name='typhoon_h480/imu_link'>
      <pose frame=''>0 0 0.16 0 0 -3.14159</pose>
      <inertial>
        <pose frame=''>0 0 0 0 -0 0</pose>
        <mass>0.015</mass>
        <inertia>
          <ixx>1e-05</ixx>
          <ixy>0</ixy>
          <ixz>0</ixz>
          <iyy>1e-05</iyy>
          <iyz>0</iyz>
          <izz>1e-05</izz>
        </inertia>
      </inertial>
      <self_collide>0</self_collide>
      <enable_wind>0</enable_wind>
      <kinematic>0</kinematic>
      <gravity>1</gravity>
    </link>

    <joint name='base_link_JOINT_0' type='fixed'>
      <parent>base_link</parent>
      <child>leg_1</child>
      <pose frame=''>0 0 0 0 -0 0</pose>
      <physics>
        <ode>
          <limit>
            <cfm>0</cfm>
            <erp>0.2</erp>
          </limit>
          <suspension>
            <cfm>0</cfm>
            <erp>0.2</erp>
          </suspension>
        </ode>
      </physics>
    </joint>

    <joint name='base_link_JOINT_1' type='fixed'>
      <parent>base_link</parent>
      <child>leg_2</child>
      <pose frame=''>0 0 0 0 -0 0</pose>
      <physics>
        <ode>
          <limit>
            <cfm>0</cfm>
            <erp>0.2</erp>
          </limit>
          <suspension>
            <cfm>0</cfm>
            <erp>0.2</erp>
          </suspension>
        </ode>
      </physics>
    </joint>

    <!--
        <joint name='cgo3_camera_joint' type='revolute'>
        <joint name='cgo3_horizontal_arm_joint' type='revolute'>

        <joint name='cgo3_vertical_arm_joint' type='revolute'>
    -->
    
    <joint name='cgo3_camera_joint' type='fixed'>
      <parent>cgo3_horizontal_arm_link</parent>
      <child>cgo3_camera_link</child>
      <pose frame=''>-0.023 0.026 -0.05001 0 -0 0</pose>
      <axis>
        <xyz>0 -1 0</xyz>
        <use_parent_model_frame>1</use_parent_model_frame>
        <limit>
          <lower>-1.05</lower>
          <upper>2.09</upper>
          <effort>100</effort>
          <velocity>-1</velocity>
        </limit>
        <dynamics>
          <spring_reference>0</spring_reference>
          <spring_stiffness>0</spring_stiffness>
          <damping>0.1</damping>
          <friction>0</friction>
        </dynamics>
      </axis>
      <physics>
        <ode>
          <limit>
            <cfm>0</cfm>
            <erp>0.2</erp>
          </limit>
          <suspension>
            <cfm>0</cfm>
            <erp>0.2</erp>
          </suspension>
        </ode>
      </physics>  
    </joint>

    <joint name='cgo3_horizontal_arm_joint' type='fixed'>
      <parent>cgo3_vertical_arm_link</parent>
      <child>cgo3_horizontal_arm_link</child>
      <pose frame=''>0.026 0 -0.0987 0 -0 0</pose>
      <axis>
        <xyz>-1 0 0</xyz>
        <use_parent_model_frame>1</use_parent_model_frame>
        <limit>
          <lower>-0.785398</lower>
          <upper>0.785398</upper>
          <effort>100</effort>
          <velocity>-1</velocity>
        </limit>
        <dynamics>
          <spring_reference>0</spring_reference>
          <spring_stiffness>0</spring_stiffness>
          <damping>0.1</damping>
          <friction>0</friction>
        </dynamics>
      </axis>
      <physics>
        <ode>
          <limit>
            <cfm>0</cfm>
            <erp>0.2</erp>
          </limit>
          <suspension>
            <cfm>0</cfm>
            <erp>0.2</erp>
          </suspension>
        </ode>
      </physics>
    </joint>

    <joint name='cgo3_mount_joint' type='revolute'>
      <parent>base_link</parent>
      <child>cgo3_mount_link</child>
      <pose frame=''>0 0 0.01 0 -0 0</pose>
      <axis>
        <xyz>0 0 1</xyz>
        <use_parent_model_frame>1</use_parent_model_frame>
        <limit>
          <lower>0</lower>
          <upper>0</upper>
          <effort>100</effort>
          <velocity>-1</velocity>
        </limit>
        <dynamics>
          <spring_reference>0</spring_reference>
          <spring_stiffness>0</spring_stiffness>
          <damping>1</damping>
          <friction>0</friction>
        </dynamics>
      </axis>
      <physics>
        <ode>
          <limit>
            <cfm>0</cfm>
            <erp>0.2</erp>
          </limit>
          <suspension>
            <cfm>0</cfm>
            <erp>0.2</erp>
          </suspension>
        </ode>
      </physics>
    </joint>

    <joint name='cgo3_vertical_arm_joint' type='fixed'>
      <parent>cgo3_mount_link</parent>
      <child>cgo3_vertical_arm_link</child>
      <pose frame=''>-0.006 0 -0.05 0 -0 0</pose>
      <axis>
        <xyz>0 0 1</xyz>
        <use_parent_model_frame>1</use_parent_model_frame>
        <limit>
          <lower>-1e+16</lower>
          <upper>1e+16</upper>
          <effort>100</effort>
          <velocity>-1</velocity>
        </limit>
        <dynamics>
          <spring_reference>0</spring_reference>
          <spring_stiffness>0</spring_stiffness>
          <damping>0.1</damping>
          <friction>0</friction>
        </dynamics>
      </axis>
      <physics>
        <ode>
          <limit>
            <cfm>0</cfm>
            <erp>0.2</erp>
          </limit>
          <suspension>
            <cfm>0</cfm>
            <erp>0.2</erp>
          </suspension>
        </ode>
      </physics>
    </joint>

    <joint name='rotor_0_joint' type='revolute'>
      <parent>base_link</parent>
      <child>rotor_0</child>
      <pose frame=''>0 0 0 0 -0 0</pose>
      <axis>
        <xyz>0.046 0.0827 1.8977</xyz>
        <use_parent_model_frame>1</use_parent_model_frame>
        <limit>
          <lower>-1e+16</lower>
          <upper>1e+16</upper>
          <effort>10</effort>
          <velocity>-1</velocity>
        </limit>
        <dynamics>
          <spring_reference>0</spring_reference>
          <spring_stiffness>0</spring_stiffness>
          <damping>0.005</damping>
          <friction>0</friction>
        </dynamics>
      </axis>
      <physics>
        <ode>
          <limit>
            <cfm>0</cfm>
            <erp>0.2</erp>
          </limit>
          <suspension>
            <cfm>0</cfm>
            <erp>0.2</erp>
          </suspension>
        </ode>
      </physics>
    </joint>

    <joint name='rotor_1_joint' type='revolute'>
      <parent>base_link</parent>
      <child>rotor_1</child>
      <pose frame=''>0.000500 -0.006000 0 0 -0 0</pose>
      <axis>
        <xyz>0.0486 0.0811 1.8976</xyz>
        <use_parent_model_frame>1</use_parent_model_frame>
        <limit>
          <lower>-1e+16</lower>
          <upper>1e+16</upper>
          <effort>10</effort>
          <velocity>-1</velocity>
        </limit>
        <dynamics>
          <spring_reference>0</spring_reference>
          <spring_stiffness>0</spring_stiffness>
          <damping>0.005</damping>
          <friction>0</friction>
        </dynamics>
      </axis>
      <physics>
        <ode>
          <limit>
            <cfm>0</cfm>
            <erp>0.2</erp>
          </limit>
          <suspension>
            <cfm>0</cfm>
            <erp>0.2</erp>
          </suspension>
        </ode>
      </physics>
    </joint>

    <joint name='rotor_2_joint' type='revolute'>
      <parent>base_link</parent>
      <child>rotor_2</child>
      <pose frame=''>0 0 0 0 -0 0</pose>
      <axis>
        <xyz>0.0404 -0.0876 1.8976</xyz>
        <use_parent_model_frame>1</use_parent_model_frame>
        <limit>
          <lower>-1e+16</lower>
          <upper>1e+16</upper>
          <effort>10</effort>
          <velocity>-1</velocity>
        </limit>
        <dynamics>
          <spring_reference>0</spring_reference>
          <spring_stiffness>0</spring_stiffness>
          <damping>0.005</damping>
          <friction>0</friction>
        </dynamics>
      </axis>
      <physics>
        <ode>
          <limit>
            <cfm>0</cfm>
            <erp>0.2</erp>
          </limit>
          <suspension>
            <cfm>0</cfm>
            <erp>0.2</erp>
          </suspension>
        </ode>
      </physics>
    </joint>

    <joint name='rotor_3_joint' type='revolute'>
      <parent>base_link</parent>
      <child>rotor_3</child>
      <pose frame=''>0 0 0 0 -0 0</pose>
      <axis>
        <xyz>0.0446 -0.0825 1.8977</xyz>
        <use_parent_model_frame>1</use_parent_model_frame>
        <limit>
          <lower>-1e+16</lower>
          <upper>1e+16</upper>
          <effort>10</effort>
          <velocity>-1</velocity>
        </limit>
        <dynamics>
          <spring_reference>0</spring_reference>
          <spring_stiffness>0</spring_stiffness>
          <damping>0.005</damping>
          <friction>0</friction>
        </dynamics>
      </axis>
      <physics>
        <ode>
          <limit>
            <cfm>0</cfm>
            <erp>0.2</erp>
          </limit>
          <suspension>
            <cfm>0</cfm>
            <erp>0.2</erp>
          </suspension>
        </ode>
      </physics>
    </joint>

    <joint name='rotor_4_joint' type='revolute'>
      <parent>base_link</parent>
      <child>rotor_4</child>
      <pose frame=''>0 0 0 0 -0 0</pose>
      <axis>
        <xyz>-0.09563 -0.0003 1.8976</xyz>
        <use_parent_model_frame>1</use_parent_model_frame>
        <limit>
          <lower>-1e+16</lower>
          <upper>1e+16</upper>
          <effort>10</effort>
          <velocity>-1</velocity>
        </limit>
        <dynamics>
          <spring_reference>0</spring_reference>
          <spring_stiffness>0</spring_stiffness>
          <damping>0.005</damping>
          <friction>0</friction>
        </dynamics>
      </axis>
      <physics>
        <ode>
          <limit>
            <cfm>0</cfm>
            <erp>0.2</erp>
          </limit>
          <suspension>
            <cfm>0</cfm>
            <erp>0.2</erp>
          </suspension>
        </ode>
      </physics>
    </joint>

    <joint name='rotor_5_joint' type='revolute'>
      <parent>base_link</parent>
      <child>rotor_5</child>
      <pose frame=''>0 0 0 0 -0 0</pose>
      <axis>
        <xyz>-0.033996 -0.0006 0.68216</xyz>
        <use_parent_model_frame>1</use_parent_model_frame>
        <limit>
          <lower>-1e+16</lower>
          <upper>1e+16</upper>
          <effort>10</effort>
          <velocity>-1</velocity>
        </limit>
        <dynamics>
          <spring_reference>0</spring_reference>
          <spring_stiffness>0</spring_stiffness>
          <damping>0.005</damping>
          <friction>0</friction>
        </dynamics>
      </axis>
      <physics>
        <ode>
          <limit>
            <cfm>0</cfm>
            <erp>0.2</erp>
          </limit>
          <suspension>
            <cfm>0</cfm>
            <erp>0.2</erp>
          </suspension>
        </ode>
      </physics>
    </joint>

    <joint name='typhoon_h480/imu_joint' type='revolute'>
      <parent>base_link</parent>
      <child>typhoon_h480/imu_link</child>
      <pose frame=''>0 0 0 0 -0 0</pose>
      <axis>
        <xyz>1 0 0</xyz>
        <use_parent_model_frame>1</use_parent_model_frame>
        <limit>
          <lower>0</lower>
          <upper>0</upper>
          <effort>0</effort>
          <velocity>0</velocity>
        </limit>
        <dynamics>
          <spring_reference>0</spring_reference>
          <spring_stiffness>0</spring_stiffness>
          <damping>0</damping>
          <friction>0</friction>
        </dynamics>
      </axis>
      <physics>
        <ode>
          <limit>
            <cfm>0</cfm>
            <erp>0.2</erp>
          </limit>
          <suspension>
            <cfm>0</cfm>
            <erp>0.2</erp>
          </suspension>
        </ode>
      </physics>
    </joint>

    <include>
      <uri>model://gps</uri>
      <pose>0 0 0.18 0 0 0</pose>
      <name>gps</name>
    </include>
    <joint name='gps_joint' type='fixed'>
      <child>gps::link</child>
      <parent>base_link</parent>
    </joint>

    <plugin name='rosbag' filename='libgazebo_multirotor_base_plugin.so'>
      <robotNamespace></robotNamespace>
      <linkName>base_link</linkName>
      <rotorVelocitySlowdownSim>10</rotorVelocitySlowdownSim>
    </plugin>
    <plugin name='front_right_motor_model' filename='libgazebo_motor_model.so'>
      <robotNamespace/>
      <jointName>rotor_0_joint</jointName>
      <linkName>rotor_0</linkName>
      <turningDirection>ccw</turningDirection>
      <timeConstantUp>0.0125</timeConstantUp>
      <timeConstantDown>0.025</timeConstantDown>
      <maxRotVelocity>1500</maxRotVelocity>
      <motorConstant>8.54858e-06</motorConstant>
      <momentConstant>0.06</momentConstant>
      <commandSubTopic>/gazebo/command/motor_speed</commandSubTopic>
      <motorNumber>4</motorNumber>
      <rotorDragCoefficient>0.000806428</rotorDragCoefficient>
      <rollingMomentCoefficient>1e-06</rollingMomentCoefficient>
      <motorSpeedPubTopic>/motor_speed/4</motorSpeedPubTopic>
      <rotorVelocitySlowdownSim>10</rotorVelocitySlowdownSim>
    </plugin>

    <plugin name='back_left_motor_model' filename='libgazebo_motor_model.so'>
      <robotNamespace/>
      <jointName>rotor_4_joint</jointName>
      <linkName>rotor_4</linkName>
      <turningDirection>cw</turningDirection>
      <timeConstantUp>0.0125</timeConstantUp>
      <timeConstantDown>0.025</timeConstantDown>
      <maxRotVelocity>1500</maxRotVelocity>
      <motorConstant>8.54858e-06</motorConstant>
      <momentConstant>0.06</momentConstant>
      <commandSubTopic>/gazebo/command/motor_speed</commandSubTopic>
      <motorNumber>0</motorNumber>
      <rotorDragCoefficient>0.000806428</rotorDragCoefficient>
      <rollingMomentCoefficient>1e-06</rollingMomentCoefficient>
      <motorSpeedPubTopic>/motor_speed/0</motorSpeedPubTopic>
      <rotorVelocitySlowdownSim>10</rotorVelocitySlowdownSim>
    </plugin>

    <plugin name='front_left_motor_model' filename='libgazebo_motor_model.so'>
      <robotNamespace/>
      <jointName>rotor_5_joint</jointName>
      <linkName>rotor_5</linkName>
      <turningDirection>ccw</turningDirection>
      <timeConstantUp>0.0125</timeConstantUp>
      <timeConstantDown>0.025</timeConstantDown>
      <maxRotVelocity>1500</maxRotVelocity>
      <motorConstant>8.54858e-06</motorConstant>
      <momentConstant>0.06</momentConstant>
      <commandSubTopic>/gazebo/command/motor_speed</commandSubTopic>
      <motorNumber>1</motorNumber>
      <rotorDragCoefficient>0.000806428</rotorDragCoefficient>
      <rollingMomentCoefficient>1e-06</rollingMomentCoefficient>
      <motorSpeedPubTopic>/motor_speed/1</motorSpeedPubTopic>
      <rotorVelocitySlowdownSim>10</rotorVelocitySlowdownSim>
    </plugin>

    <plugin name='back_right_motor_model' filename='libgazebo_motor_model.so'>
      <robotNamespace/>
      <jointName>rotor_3_joint</jointName>
      <linkName>rotor_3</linkName>
      <turningDirection>ccw</turningDirection>
      <timeConstantUp>0.0125</timeConstantUp>
      <timeConstantDown>0.025</timeConstantDown>
      <maxRotVelocity>1500</maxRotVelocity>
      <motorConstant>8.54858e-06</motorConstant>
      <momentConstant>0.06</momentConstant>
      <commandSubTopic>/gazebo/command/motor_speed</commandSubTopic>
      <motorNumber>3</motorNumber>
      <rotorDragCoefficient>0.000806428</rotorDragCoefficient>
      <rollingMomentCoefficient>1e-06</rollingMomentCoefficient>
      <motorSpeedPubTopic>/motor_speed/3</motorSpeedPubTopic>
      <rotorVelocitySlowdownSim>10</rotorVelocitySlowdownSim>
    </plugin>

    <plugin name='back_left_motor_model' filename='libgazebo_motor_model.so'>
      <robotNamespace/>
      <jointName>rotor_2_joint</jointName>
      <linkName>rotor_2</linkName>
      <turningDirection>cw</turningDirection>
      <timeConstantUp>0.0125</timeConstantUp>
      <timeConstantDown>0.025</timeConstantDown>
      <maxRotVelocity>1500</maxRotVelocity>
      <motorConstant>8.54858e-06</motorConstant>
      <momentConstant>0.06</momentConstant>
      <commandSubTopic>/gazebo/command/motor_speed</commandSubTopic>
      <motorNumber>2</motorNumber>
      <rotorDragCoefficient>0.000806428</rotorDragCoefficient>
      <rollingMomentCoefficient>1e-06</rollingMomentCoefficient>
      <motorSpeedPubTopic>/motor_speed/4</motorSpeedPubTopic>
      <rotorVelocitySlowdownSim>10</rotorVelocitySlowdownSim>
    </plugin>

    <plugin name='front_left_motor_model' filename='libgazebo_motor_model.so'>
      <robotNamespace/>
      <jointName>rotor_1_joint</jointName>
      <linkName>rotor_1</linkName>
      <turningDirection>cw</turningDirection>
      <timeConstantUp>0.0125</timeConstantUp>
      <timeConstantDown>0.025</timeConstantDown>
      <maxRotVelocity>1500</maxRotVelocity>
      <motorConstant>8.54858e-06</motorConstant>
      <momentConstant>0.06</momentConstant>
      <commandSubTopic>/gazebo/command/motor_speed</commandSubTopic>
      <motorNumber>1</motorNumber>
      <rotorDragCoefficient>0.000806428</rotorDragCoefficient>
      <rollingMomentCoefficient>1e-06</rollingMomentCoefficient>
      <motorSpeedPubTopic>/motor_speed/4</motorSpeedPubTopic>
      <rotorVelocitySlowdownSim>10</rotorVelocitySlowdownSim>
    </plugin>
    <plugin name='groundtruth_plugin' filename='libgazebo_groundtruth_plugin.so'>
      <robotNamespace/>
    </plugin>  
    <plugin name='magnetometer_plugin' filename='libgazebo_magnetometer_plugin.so'>
      <robotNamespace/>
      <pubRate>100</pubRate>
      <noiseDensity>0.0004</noiseDensity>
      <randomWalk>6.4e-06</randomWalk>
      <biasCorrelationTime>600</biasCorrelationTime>
      <magTopic>/mag</magTopic>
    </plugin>
    <plugin name='barometer_plugin' filename='libgazebo_barometer_plugin.so'>
      <robotNamespace/>
      <pubRate>50</pubRate>
      <baroTopic>/baro</baroTopic>
    </plugin>
    <plugin name='mavlink_interface' filename='libgazebo_mavlink_interface.so'>
      <robotNamespace></robotNamespace>
      <imuSubTopic>/imu</imuSubTopic>
      <magSubTopic>/mag</magSubTopic>
      <baroSubTopic>/baro</baroSubTopic>
      <mavlink_addr>INADDR_ANY</mavlink_addr>
      <mavlink_tcp_port>4560</mavlink_tcp_port>
      <mavlink_udp_port>14560</mavlink_udp_port>
      <serialEnabled>0</serialEnabled>
      <serialDevice>/dev/ttyACM0</serialDevice>
      <baudRate>921600</baudRate>
      <qgc_addr>INADDR_ANY</qgc_addr>
      <qgc_udp_port>14550</qgc_udp_port>
      <sdk_addr>INADDR_ANY</sdk_addr>
      <sdk_udp_port>14540</sdk_udp_port>
      <hil_mode>0</hil_mode>
      <hil_state_level>false</hil_state_level>
      <enable_lockstep>true</enable_lockstep>
      <use_tcp>true</use_tcp>
      <motorSpeedCommandPubTopic>/gazebo/command/motor_speed</motorSpeedCommandPubTopic>
      <control_channels>
        <channel name='rotor0'>
          <input_index>0</input_index>
          <input_offset>0</input_offset>
          <input_scaling>1500</input_scaling>
          <zero_position_disarmed>0</zero_position_disarmed>
          <zero_position_armed>100</zero_position_armed>
          <joint_control_type>velocity</joint_control_type>
          <joint_name>rotor_0_joint</joint_name>
        </channel>
        <channel name='rotor1'>
          <input_index>1</input_index>
          <input_offset>0</input_offset>
          <input_scaling>1500</input_scaling>
          <zero_position_disarmed>0</zero_position_disarmed>
          <zero_position_armed>100</zero_position_armed>
          <joint_control_type>velocity</joint_control_type>
          <joint_name>rotor_1_joint</joint_name>
        </channel>
        <channel name='rotor2'>
          <input_index>2</input_index>
          <input_offset>0</input_offset>
          <input_scaling>1500</input_scaling>
          <zero_position_disarmed>0</zero_position_disarmed>
          <zero_position_armed>100</zero_position_armed>
          <joint_control_type>velocity</joint_control_type>
          <joint_name>rotor_2_joint</joint_name>
        </channel>
        <channel name='rotor3'>
          <input_index>3</input_index>
          <input_offset>0</input_offset>
          <input_scaling>1500</input_scaling>
          <zero_position_disarmed>0</zero_position_disarmed>
          <zero_position_armed>100</zero_position_armed>
          <joint_control_type>velocity</joint_control_type>
          <joint_name>rotor_3_joint</joint_name>
        </channel>
        <channel name='rotor4'>
          <input_index>4</input_index>
          <input_offset>0</input_offset>
          <input_scaling>1500</input_scaling>
          <zero_position_disarmed>0</zero_position_disarmed>
          <zero_position_armed>100</zero_position_armed>
          <joint_control_type>velocity</joint_control_type>
          <joint_name>rotor_4_joint</joint_name>
        </channel>
        <channel name='rotor5'>
          <input_index>5</input_index>
          <input_offset>0</input_offset>
          <input_scaling>1500</input_scaling>
          <zero_position_disarmed>0</zero_position_disarmed>
          <zero_position_armed>100</zero_position_armed>
          <joint_control_type>velocity</joint_control_type>
          <joint_name>rotor_5_joint</joint_name>
        </channel>
        <channel name='gimbal_roll'>
          <input_index>6</input_index>
          <input_offset>0</input_offset>
          <input_scaling>-3.1415</input_scaling>
          <zero_position_disarmed>0</zero_position_disarmed>
          <zero_position_armed>0</zero_position_armed>
          <joint_control_type>position_gztopic</joint_control_type>
          <gztopic>/gimbal_roll_cmd</gztopic>
          <joint_name>typhoon_h480::cgo3_camera_joint</joint_name>
        </channel>
        <channel name='gimbal_pitch'>
          <input_index>7</input_index>
          <input_offset>0</input_offset>
          <input_scaling>3.1415</input_scaling>
          <zero_position_disarmed>0</zero_position_disarmed>
          <zero_position_armed>0</zero_position_armed>
          <joint_control_type>position_gztopic</joint_control_type>
          <gztopic>/gimbal_pitch_cmd</gztopic>
          <joint_name>typhoon_h480::cgo3_camera_joint</joint_name>
        </channel>
        <channel name='gimbal_yaw'>
          <input_index>8</input_index>
          <input_offset>0</input_offset>
          <input_scaling>-3.1415</input_scaling>
          <zero_position_disarmed>0</zero_position_disarmed>
          <zero_position_armed>0</zero_position_armed>
          <joint_control_type>position_gztopic</joint_control_type>
          <gztopic>/gimbal_yaw_cmd</gztopic>
          <joint_name>typhoon_h480::cgo3_vertical_arm_joint</joint_name>
        </channel>
      </control_channels>
    </plugin>  
    <plugin name='gazebo_imu_plugin' filename='libgazebo_imu_plugin.so'>
      <robotNamespace/>
      <linkName>typhoon_h480/imu_link</linkName>
      <imuTopic>/imu</imuTopic>
      <gyroscopeNoiseDensity>0.0003394</gyroscopeNoiseDensity>
      <gyroscopeRandomWalk>3.8785e-05</gyroscopeRandomWalk>
      <gyroscopeBiasCorrelationTime>1000.0</gyroscopeBiasCorrelationTime>
      <gyroscopeTurnOnBiasSigma>0.0087</gyroscopeTurnOnBiasSigma>
      <accelerometerNoiseDensity>0.004</accelerometerNoiseDensity>
      <accelerometerRandomWalk>0.006</accelerometerRandomWalk>
      <accelerometerBiasCorrelationTime>300.0</accelerometerBiasCorrelationTime>
      <accelerometerTurnOnBiasSigma>0.196</accelerometerTurnOnBiasSigma>
    </plugin>
    <plugin name='gimbal_controller' filename='libgazebo_gimbal_controller_plugin.so'>
      <joint_yaw>typhoon_h480::cgo3_vertical_arm_joint</joint_yaw>
      <joint_roll>typhoon_h480::cgo3_horizontal_arm_joint</joint_roll>
      <joint_pitch>typhoon_h480::cgo3_camera_joint</joint_pitch>
      <control_gimbal_channels>
        <channel>
          <joint_control_pid>
            <p>0.8</p>
            <i>0.1</i>
            <d>0.02</d>
            <iMax>0</iMax>
            <iMin>0</iMin>
            <cmdMax>1.0</cmdMax>
            <cmdMin>-1.0</cmdMin>
          </joint_control_pid>
          <joint_axis>joint_yaw</joint_axis>
        </channel>
        <channel>
          <joint_control_pid>
            <p>0.8</p>
            <i>0.035</i>
            <d>0.02</d>
            <iMax>0</iMax>
            <iMin>0</iMin>
            <cmdMax>0.3</cmdMax>
            <cmdMin>-0.3</cmdMin>
          </joint_control_pid>
          <joint_axis>joint_roll</joint_axis>
        </channel>
        <channel>
          <joint_control_pid>
            <p>2.068</p>
            <i>0.01245</i>
            <d>0.01</d>
            <iMax>0</iMax>
            <iMin>0</iMin>
            <cmdMax>0.3</cmdMax>
            <cmdMin>-0.3</cmdMin>
          </joint_control_pid>
          <joint_axis>joint_pitch</joint_axis>
        </channel>
      </control_gimbal_channels>
      <gimbal_imu>camera_imu</gimbal_imu>
    </plugin>
  </model>
</sdf>